Workbook

Sheet Premissas
A1: Relatório de custo de mensagens Blip
A3: Categoria | C3: Tarifa por mensagem entregue (R$)
A4: Utilidade | C4: 0.09
A5: Marketing Lite | C5: 0.54
A6: Marketing | C6: 0.6
A7: Autenticação | C7: 0
A9: Início da 1ª semana | C9: 46296
A10: Fim da 1ª semana | C10: 46301
A12: Contatos de disparo
A13: Contato | B13: Disparos entregues | C13: % do total | D13: Utilidade | E13: Marketing Lite | F13: Serviço
A14: +55 11 93270 1695 | B14: =SUM(D14:F14) -> 34462 | C14: =IF($B$17=0,0,B14/$B$17) -> 0.17658422 | D14: 29153 | E14: 5309 | F14: 0
A15: +55 11 95231 1000 | B15: =SUM(D15:F15) -> 137281 | C15: =IF($B$17=0,0,B15/$B$17) -> 0.70343156 | D15: 127788 | E15: 5675 | F15: 3818
A16: +55 11 96414 0786 | B16: =SUM(D16:F16) -> 23416 | C16: =IF($B$17=0,0,B16/$B$17) -> 0.11998422 | D16: 20708 | E16: 0 | F16: 2708
A17: Total | B17: =SUM(B14:B16) -> 195159 | C17: =SUM(C14:C16) -> 1 | D17: =SUM(D14:D16) -> 177649 | E17: =SUM(E14:E16) -> 10984 | F17: =SUM(F14:F16) -> 6526
A19: Fonte: Blip, Números de telefone, mensagens pagas (print de 15/10, acumulado de 01/10 a 14/10).
A20: Marketing e Autenticação sem envios. Serviço não tem tarifa e não entra no cálculo de custo.
A22: Tarifas por mês: a aba Tarifas por mês guarda as tarifas de jan/25 a set/26. Meses fora dela (out/26 em diante) usam as tarifas acima.

Sheet Diário
A1: Contagem diária de mensagens pagas entregues
A4: Data | B4: Utilidade | C4: Autenticação | D4: Marketing | E4: Marketing Lite | F4: Total de mensagens | G4: Custo (R$) | H4: Mês
A5: 46296 | B5: 32 | C5: 0 | D5: 0 | E5: 3 | F5: =IF(A5="","",SUM(B5:E5)) -> 35 | G5: =IF(A5="","",B5*Premissas!$C$4+C5*Premissas!$C$7+D5*Premissas!$C$6+E5*Premissas!$C$5) -> 4.5 | H5: =IF(A5="","",DATE(YEAR(A5),MONTH(A5),1)) -> 46296
A6: 46297 | B6: 9012 | C6: 0 | D6: 0 | E6: 2 | F6: =IF(A6="","",SUM(B6:E6)) -> 9014 | G6: =IF(A6="","",B6*Premissas!$C$4+C6*Premissas!$C$7+D6*Premissas!$C$6+E6*Premissas!$C$5) -> 812.16 | H6: =IF(A6="","",DATE(YEAR(A6),MONTH(A6),1)) -> 46296
A7: 46298 | B7: 10694 | C7: 0 | D7: 0 | E7: 1 | F7: =IF(A7="","",SUM(B7:E7)) -> 10695 | G7: =IF(A7="","",B7*Premissas!$C$4+C7*Premissas!$C$7+D7*Premissas!$C$6+E7*Premissas!$C$5) -> 963 | H7: =IF(A7="","",DATE(YEAR(A7),MONTH(A7),1)) -> 46296
A8: 46299 | B8: 13503 | C8: 0 | D8: 0 | E8: 1 | F8: =IF(A8="","",SUM(B8:E8)) -> 13504 | G8: =IF(A8="","",B8*Premissas!$C$4+C8*Premissas!$C$7+D8*Premissas!$C$6+E8*Premissas!$C$5) -> 1215.81 | H8: =IF(A8="","",DATE(YEAR(A8),MONTH(A8),1)) -> 46296
A9: 46300 | B9: 21812 | C9: 0 | D9: 0 | E9: 0 | F9: =IF(A9="","",SUM(B9:E9)) -> 21812 | G9: =IF(A9="","",B9*Premissas!$C$4+C9*Premissas!$C$7+D9*Premissas!$C$6+E9*Premissas!$C$5) -> 1963.08 | H9: =IF(A9="","",DATE(YEAR(A9),MONTH(A9),1)) -> 46296
A10: 46301 | B10: 27289 | C10: 0 | D10: 0 | E10: 9332 | F10: =IF(A10="","",SUM(B10:E10)) -> 36621 | G10: =IF(A10="","",B10*Premissas!$C$4+C10*Premissas!$C$7+D10*Premissas!$C$6+E10*Premissas!$C$5) -> 7495.29 | H10: =IF(A10="","",DATE(YEAR(A10),MONTH(A10),1)) -> 46296 | I10: Revendo meta valor cai para (3.295,89)
A11: 46302 | B11: 36873 | C11: 0 | D11: 0 | E11: 63 | F11: =IF(A11="","",SUM(B11:E11)) -> 36936 | G11: =IF(A11="","",B11*Premissas!$C$4+C11*Premissas!$C$7+D11*Premissas!$C$6+E11*Premissas!$C$5) -> 3352.59 | H11: =IF(A11="","",DATE(YEAR(A11),MONTH(A11),1)) -> 46296
A12: 46303 | B12: 12063 | C12: 0 | D12: 0 | E12: 9 | F12: =IF(A12="","",SUM(B12:E12)) -> 12072 | G12: =IF(A12="","",B12*Premissas!$C$4+C12*Premissas!$C$7+D12*Premissas!$C$6+E12*Premissas!$C$5) -> 1090.53 | H12: =IF(A12="","",DATE(YEAR(A12),MONTH(A12),1)) -> 46296
A13: 46304 | B13: 95 | C13: 0 | D13: 0 | E13: 4 | F13: =IF(A13="","",SUM(B13:E13)) -> 99 | G13: =IF(A13="","",B13*Premissas!$C$4+C13*Premissas!$C$7+D13*Premissas!$C$6+E13*Premissas!$C$5) -> 10.71 | H13: =IF(A13="","",DATE(YEAR(A13),MONTH(A13),1)) -> 46296
A14: 46305 | B14: 5185 | C14: 0 | D14: 0 | E14: 1 | F14: =IF(A14="","",SUM(B14:E14)) -> 5186 | G14: =IF(A14="","",B14*Premissas!$C$4+C14*Premissas!$C$7+D14*Premissas!$C$6+E14*Premissas!$C$5) -> 467.19 | H14: =IF(A14="","",DATE(YEAR(A14),MONTH(A14),1)) -> 46296
A15: 46306 | B15: 8957 | C15: 0 | D15: 0 | E15: 0 | F15: =IF(A15="","",SUM(B15:E15)) -> 8957 | G15: =IF(A15="","",B15*Premissas!$C$4+C15*Premissas!$C$7+D15*Premissas!$C$6+E15*Premissas!$C$5) -> 806.13 | H15: =IF(A15="","",DATE(YEAR(A15),MONTH(A15),1)) -> 46296
A16: 46307 | B16: 3558 | C16: 0 | D16: 0 | E16: 1560 | F16: =IF(A16="","",SUM(B16:E16)) -> 5118 | G16: =IF(A16="","",B16*Premissas!$C$4+C16*Premissas!$C$7+D16*Premissas!$C$6+E16*Premissas!$C$5) -> 1162.62 | H16: =IF(A16="","",DATE(YEAR(A16),MONTH(A16),1)) -> 46296
A17: 46308 | B17: 11134 | C17: 0 | D17: 0 | E17: 8 | F17: =IF(A17="","",SUM(B17:E17)) -> 11142 | G17: =IF(A17="","",B17*Premissas!$C$4+C17*Premissas!$C$7+D17*Premissas!$C$6+E17*Premissas!$C$5) -> 1006.38 | H17: =IF(A17="","",DATE(YEAR(A17),MONTH(A17),1)) -> 46296
F18: =IF(A18="","",SUM(B18:E18)) | G18: =IF(A18="","",B18*Premissas!$C$4+C18*Premissas!$C$7+D18*Premissas!$C$6+E18*Premissas!$C$5) | H18: =IF(A18="","",DATE(YEAR(A18),MONTH(A18),1))
F19: =IF(A19="","",SUM(B19:E19)) | G19: =IF(A19="","",B19*Premissas!$C$4+C19*Premissas!$C$7+D19*Premissas!$C$6+E19*Premissas!$C$5) | H19: =IF(A19="","",DATE(YEAR(A19),MONTH(A19),1))
F20: =IF(A20="","",SUM(B20:E20)) | G20: =IF(A20="","",B20*Premissas!$C$4+C20*Premissas!$C$7+D20*Premissas!$C$6+E20*Premissas!$C$5) | H20: =IF(A20="","",DATE(YEAR(A20),MONTH(A20),1))
F21: =IF(A21="","",SUM(B21:E21)) | G21: =IF(A21="","",B21*Premissas!$C$4+C21*Premissas!$C$7+D21*Premissas!$C$6+E21*Premissas!$C$5) | H21: =IF(A21="","",DATE(YEAR(A21),MONTH(A21),1))
F22: =IF(A22="","",SUM(B22:E22)) | G22: =IF(A22="","",B22*Premissas!$C$4+C22*Premissas!$C$7+D22*Premissas!$C$6+E22*Premissas!$C$5) | H22: =IF(A22="","",DATE(YEAR(A22),MONTH(A22),1))
F23: =IF(A23="","",SUM(B23:E23)) | G23: =IF(A23="","",B23*Premissas!$C$4+C23*Premissas!$C$7+D23*Premissas!$C$6+E23*Premissas!$C$5) | H23: =IF(A23="","",DATE(YEAR(A23),MONTH(A23),1))
F24: =IF(A24="","",SUM(B24:E24)) | G24: =IF(A24="","",B24*Premissas!$C$4+C24*Premissas!$C$7+D24*Premissas!$C$6+E24*Premissas!$C$5) | H24: =IF(A24="","",DATE(YEAR(A24),MONTH(A24),1))
F25: =IF(A25="","",SUM(B25:E25)) | G25: =IF(A25="","",B25*Premissas!$C$4+C25*Premissas!$C$7+D25*Premissas!$C$6+E25*Premissas!$C$5) | H25: =IF(A25="","",DATE(YEAR(A25),MONTH(A25),1))
F26: =IF(A26="","",SUM(B26:E26)) | G26: =IF(A26="","",B26*Premissas!$C$4+C26*Premissas!$C$7+D26*Premissas!$C$6+E26*Premissas!$C$5) | H26: =IF(A26="","",DATE(YEAR(A26),MONTH(A26),1))
F27: =IF(A27="","",SUM(B27:E27)) | G27: =IF(A27="","",B27*Premissas!$C$4+C27*Premissas!$C$7+D27*Premissas!$C$6+E27*Premissas!$C$5) | H27: =IF(A27="","",DATE(YEAR(A27),MONTH(A27),1))
F28: =IF(A28="","",SUM(B28:E28)) | G28: =IF(A28="","",B28*Premissas!$C$4+C28*Premissas!$C$7+D28*Premissas!$C$6+E28*Premissas!$C$5) | H28: =IF(A28="","",DATE(YEAR(A28),MONTH(A28),1))
F29: =IF(A29="","",SUM(B29:E29)) | G29: =IF(A29="","",B29*Premissas!$C$4+C29*Premissas!$C$7+D29*Premissas!$C$6+E29*Premissas!$C$5) | H29: =IF(A29="","",DATE(YEAR(A29),MONTH(A29),1))
... F400: =IF(A400="","",SUM(B400:E400)) | G400: =IF(A400="","",B400*Premissas!$C$4+C400*Premissas!$C$7+D400*Premissas!$C$6+E400*Premissas!$C$5) | H400: =IF(A400="","",DATE(YEAR(A400),MONTH(A400),1))

Sheet Semanal
A1: Relatório semanal (Quinta a Quarta)
A2: Semana 1 definida em Premissas (início e fim). As demais têm 7 dias, a partir do dia seguinte. A última pode estar parcial (veja Dias com dados).
A4: Início | B4: Fim | C4: Dias com dados | D4: Utilidade | E4: Marketing Lite | F4: Marketing | G4: Autenticação | H4: Total de mensagens | I4: Custo (R$) | J4: Custo médio por mensagem (R$) | K4: % do custo em Marketing Lite | L4: Variação do custo vs. semana anterior
A5: =IF(COUNT(Diário!$A$5:$A$400)=0,"",Premissas!$C$9) -> 46296 | B5: =IF(A5="","",Premissas!$C$10) -> 46301 | C5: =IF(A5="","",COUNTIFS(Diário!$A$5:$A$400,">="&$A5,Diário!$A$5:$A$400,"<="&$B5)) -> 6 | D5: =IF($A5="","",SUMIFS(Diário!$B$5:$B$400,Diário!$A$5:$A$400,">="&$A5,Diário!$A$5:$A$400,"<="&$B5)) -> 82342 | E5: =IF($A5="","",SUMIFS(Diário!$E$5:$E$400,Diário!$A$5:$A$400,">="&$A5,Diário!$A$5:$A$400,"<="&$B5)) -> 9339 | F5: =IF($A5="","",SUMIFS(Diário!$D$5:$D$400,Diário!$A$5:$A$400,">="&$A5,Diário!$A$5:$A$400,"<="&$B5)) -> 0 | G5: =IF($A5="","",SUMIFS(Diário!$C$5:$C$400,Diário!$A$5:$A$400,">="&$A5,Diário!$A$5:$A$400,"<="&$B5)) -> 0 | H5: =IF(A5="","",SUM(D5:G5)) -> 91681 | I5: =IF($A5="","",SUMIFS(Diário!$G$5:$G$400,Diário!$A$5:$A$400,">="&$A5,Diário!$A$5:$A$400,"<="&$B5)) -> 12453.84 | J5: =IF(A5="","",IF(H5=0,0,I5/H5)) -> 0.13583883 | K5: =IF(A5="","",IF(I5=0,0,E5*Premissas!$C$5/I5)) -> 0.40494016 | L5: =IF(A5="","","n/d") -> n/d
A6: =IF(B5="","",IF(B5+1>MAX(Diário!$A$5:$A$400),"",B5+1)) -> 46302 | B6: =IF(A6="","",A6+6) -> 46308 | C6: =IF(A6="","",COUNTIFS(Diário!$A$5:$A$400,">="&$A6,Diário!$A$5:$A$400,"<="&$B6)) -> 7 | D6: =IF($A6="","",SUMIFS(Diário!$B$5:$B$400,Diário!$A$5:$A$400,">="&$A6,Diário!$A$5:$A$400,"<="&$B6)) -> 77865 | E6: =IF($A6="","",SUMIFS(Diário!$E$5:$E$400,Diário!$A$5:$A$400,">="&$A6,Diário!$A$5:$A$400,"<="&$B6)) -> 1645 | F6: =IF($A6="","",SUMIFS(Diário!$D$5:$D$400,Diário!$A$5:$A$400,">="&$A6,Diário!$A$5:$A$400,"<="&$B6)) -> 0 | G6: =IF($A6="","",SUMIFS(Diário!$C$5:$C$400,Diário!$A$5:$A$400,">="&$A6,Diário!$A$5:$A$400,"<="&$B6)) -> 0 | H6: =IF(A6="","",SUM(D6:G6)) -> 79510 | I6: =IF($A6="","",SUMIFS(Diário!$G$5:$G$400,Diário!$A$5:$A$400,">="&$A6,Diário!$A$5:$A$400,"<="&$B6)) -> 7896.15 | J6: =IF(A6="","",IF(H6=0,0,I6/H6)) -> 0.09931015 | K6: =IF(A6="","",IF(I6=0,0,E6*Premissas!$C$5/I6)) -> 0.11249786 | L6: =IF(A6="","",IF(I5=0,"n/d",I6/I5-1)) -> -0.36596664
A7: =IF(B6="","",IF(B6+1>MAX(Diário!$A$5:$A$400),"",B6+1)) | B7: =IF(A7="","",A7+6) | C7: =IF(A7="","",COUNTIFS(Diário!$A$5:$A$400,">="&$A7,Diário!$A$5:$A$400,"<="&$B7)) | D7: =IF($A7="","",SUMIFS(Diário!$B$5:$B$400,Diário!$A$5:$A$400,">="&$A7,Diário!$A$5:$A$400,"<="&$B7)) | E7: =IF($A7="","",SUMIFS(Diário!$E$5:$E$400,Diário!$A$5:$A$400,">="&$A7,Diário!$A$5:$A$400,"<="&$B7)) | F7: =IF($A7="","",SUMIFS(Diário!$D$5:$D$400,Diário!$A$5:$A$400,">="&$A7,Diário!$A$5:$A$400,"<="&$B7)) | G7: =IF($A7="","",SUMIFS(Diário!$C$5:$C$400,Diário!$A$5:$A$400,">="&$A7,Diário!$A$5:$A$400,"<="&$B7)) | H7: =IF(A7="","",SUM(D7:G7)) | I7: =IF($A7="","",SUMIFS(Diário!$G$5:$G$400,Diário!$A$5:$A$400,">="&$A7,Diário!$A$5:$A$400,"<="&$B7)) | J7: =IF(A7="","",IF(H7=0,0,I7/H7)) | K7: =IF(A7="","",IF(I7=0,0,E7*Premissas!$C$5/I7)) | L7: =IF(A7="","",IF(I6=0,"n/d",I7/I6-1))
A8: =IF(B7="","",IF(B7+1>MAX(Diário!$A$5:$A$400),"",B7+1)) | B8: =IF(A8="","",A8+6) | C8: =IF(A8="","",COUNTIFS(Diário!$A$5:$A$400,">="&$A8,Diário!$A$5:$A$400,"<="&$B8)) | D8: =IF($A8="","",SUMIFS(Diário!$B$5:$B$400,Diário!$A$5:$A$400,">="&$A8,Diário!$A$5:$A$400,"<="&$B8)) | E8: =IF($A8="","",SUMIFS(Diário!$E$5:$E$400,Diário!$A$5:$A$400,">="&$A8,Diário!$A$5:$A$400,"<="&$B8)) | F8: =IF($A8="","",SUMIFS(Diário!$D$5:$D$400,Diário!$A$5:$A$400,">="&$A8,Diário!$A$5:$A$400,"<="&$B8)) | G8: =IF($A8="","",SUMIFS(Diário!$C$5:$C$400,Diário!$A$5:$A$400,">="&$A8,Diário!$A$5:$A$400,"<="&$B8)) | H8: =IF(A8="","",SUM(D8:G8)) | I8: =IF($A8="","",SUMIFS(Diário!$G$5:$G$400,Diário!$A$5:$A$400,">="&$A8,Diário!$A$5:$A$400,"<="&$B8)) | J8: =IF(A8="","",IF(H8=0,0,I8/H8)) | K8: =IF(A8="","",IF(I8=0,0,E8*Premissas!$C$5/I8)) | L8: =IF(A8="","",IF(I7=0,"n/d",I8/I7-1))
A9: =IF(B8="","",IF(B8+1>MAX(Diário!$A$5:$A$400),"",B8+1)) | B9: =IF(A9="","",A9+6) | C9: =IF(A9="","",COUNTIFS(Diário!$A$5:$A$400,">="&$A9,Diário!$A$5:$A$400,"<="&$B9)) | D9: =IF($A9="","",SUMIFS(Diário!$B$5:$B$400,Diário!$A$5:$A$400,">="&$A9,Diário!$A$5:$A$400,"<="&$B9)) | E9: =IF($A9="","",SUMIFS(Diário!$E$5:$E$400,Diário!$A$5:$A$400,">="&$A9,Diário!$A$5:$A$400,"<="&$B9)) | F9: =IF($A9="","",SUMIFS(Diário!$D$5:$D$400,Diário!$A$5:$A$400,">="&$A9,Diário!$A$5:$A$400,"<="&$B9)) | G9: =IF($A9="","",SUMIFS(Diário!$C$5:$C$400,Diário!$A$5:$A$400,">="&$A9,Diário!$A$5:$A$400,"<="&$B9)) | H9: =IF(A9="","",SUM(D9:G9)) | I9: =IF($A9="","",SUMIFS(Diário!$G$5:$G$400,Diário!$A$5:$A$400,">="&$A9,Diário!$A$5:$A$400,"<="&$B9)) | J9: =IF(A9="","",IF(H9=0,0,I9/H9)) | K9: =IF(A9="","",IF(I9=0,0,E9*Premissas!$C$5/I9)) | L9: =IF(A9="","",IF(I8=0,"n/d",I9/I8-1))
A10: =IF(B9="","",IF(B9+1>MAX(Diário!$A$5:$A$400),"",B9+1)) | B10: =IF(A10="","",A10+6) | C10: =IF(A10="","",COUNTIFS(Diário!$A$5:$A$400,">="&$A10,Diário!$A$5:$A$400,"<="&$B10)) | D10: =IF($A10="","",SUMIFS(Diário!$B$5:$B$400,Diário!$A$5:$A$400,">="&$A10,Diário!$A$5:$A$400,"<="&$B10)) | E10: =IF($A10="","",SUMIFS(Diário!$E$5:$E$400,Diário!$A$5:$A$400,">="&$A10,Diário!$A$5:$A$400,"<="&$B10)) | F10: =IF($A10="","",SUMIFS(Diário!$D$5:$D$400,Diário!$A$5:$A$400,">="&$A10,Diário!$A$5:$A$400,"<="&$B10)) | G10: =IF($A10="","",SUMIFS(Diário!$C$5:$C$400,Diário!$A$5:$A$400,">="&$A10,Diário!$A$5:$A$400,"<="&$B10)) | H10: =IF(A10="","",SUM(D10:G10)) | I10: =IF($A10="","",SUMIFS(Diário!$G$5:$G$400,Diário!$A$5:$A$400,">="&$A10,Diário!$A$5:$A$400,"<="&$B10)) | J10: =IF(A10="","",IF(H10=0,0,I10/H10)) | K10: =IF(A10="","",IF(I10=0,0,E10*Premissas!$C$5/I10)) | L10: =IF(A10="","",IF(I9=0,"n/d",I10/I9-1))
A11: =IF(B10="","",IF(B10+1>MAX(Diário!$A$5:$A$400),"",B10+1)) | B11: =IF(A11="","",A11+6) | C11: =IF(A11="","",COUNTIFS(Diário!$A$5:$A$400,">="&$A11,Diário!$A$5:$A$400,"<="&$B11)) | D11: =IF($A11="","",SUMIFS(Diário!$B$5:$B$400,Diário!$A$5:$A$400,">="&$A11,Diário!$A$5:$A$400,"<="&$B11)) | E11: =IF($A11="","",SUMIFS(Diário!$E$5:$E$400,Diário!$A$5:$A$400,">="&$A11,Diário!$A$5:$A$400,"<="&$B11)) | F11: =IF($A11="","",SUMIFS(Diário!$D$5:$D$400,Diário!$A$5:$A$400,">="&$A11,Diário!$A$5:$A$400,"<="&$B11)) | G11: =IF($A11="","",SUMIFS(Diário!$C$5:$C$400,Diário!$A$5:$A$400,">="&$A11,Diário!$A$5:$A$400,"<="&$B11)) | H11: =IF(A11="","",SUM(D11:G11)) | I11: =IF($A11="","",SUMIFS(Diário!$G$5:$G$400,Diário!$A$5:$A$400,">="&$A11,Diário!$A$5:$A$400,"<="&$B11)) | J11: =IF(A11="","",IF(H11=0,0,I11/H11)) | K11: =IF(A11="","",IF(I11=0,0,E11*Premissas!$C$5/I11)) | L11: =IF(A11="","",IF(I10=0,"n/d",I11/I10-1))
A12: =IF(B11="","",IF(B11+1>MAX(Diário!$A$5:$A$400),"",B11+1)) | B12: =IF(A12="","",A12+6) | C12: =IF(A12="","",COUNTIFS(Diário!$A$5:$A$400,">="&$A12,Diário!$A$5:$A$400,"<="&$B12)) | D12: =IF($A12="","",SUMIFS(Diário!$B$5:$B$400,Diário!$A$5:$A$400,">="&$A12,Diário!$A$5:$A$400,"<="&$B12)) | E12: =IF($A12="","",SUMIFS(Diário!$E$5:$E$400,Diário!$A$5:$A$400,">="&$A12,Diário!$A$5:$A$400,"<="&$B12)) | F12: =IF($A12="","",SUMIFS(Diário!$D$5:$D$400,Diário!$A$5:$A$400,">="&$A12,Diário!$A$5:$A$400,"<="&$B12)) | G12: =IF($A12="","",SUMIFS(Diário!$C$5:$C$400,Diário!$A$5:$A$400,">="&$A12,Diário!$A$5:$A$400,"<="&$B12)) | H12: =IF(A12="","",SUM(D12:G12)) | I12: =IF($A12="","",SUMIFS(Diário!$G$5:$G$400,Diário!$A$5:$A$400,">="&$A12,Diário!$A$5:$A$400,"<="&$B12)) | J12: =IF(A12="","",IF(H12=0,0,I12/H12)) | K12: =IF(A12="","",IF(I12=0,0,E12*Premissas!$C$5/I12)) | L12: =IF(A12="","",IF(I11=0,"n/d",I12/I11-1))
A13: =IF(B12="","",IF(B12+1>MAX(Diário!$A$5:$A$400),"",B12+1)) | B13: =IF(A13="","",A13+6) | C13: =IF(A13="","",COUNTIFS(Diário!$A$5:$A$400,">="&$A13,Diário!$A$5:$A$400,"<="&$B13)) | D13: =IF($A13="","",SUMIFS(Diário!$B$5:$B$400,Diário!$A$5:$A$400,">="&$A13,Diário!$A$5:$A$400,"<="&$B13)) | E13: =IF($A13="","",SUMIFS(Diário!$E$5:$E$400,Diário!$A$5:$A$400,">="&$A13,Diário!$A$5:$A$400,"<="&$B13)) | F13: =IF($A13="","",SUMIFS(Diário!$D$5:$D$400,Diário!$A$5:$A$400,">="&$A13,Diário!$A$5:$A$400,"<="&$B13)) | G13: =IF($A13="","",SUMIFS(Diário!$C$5:$C$400,Diário!$A$5:$A$400,">="&$A13,Diário!$A$5:$A$400,"<="&$B13)) | H13: =IF(A13="","",SUM(D13:G13)) | I13: =IF($A13="","",SUMIFS(Diário!$G$5:$G$400,Diário!$A$5:$A$400,">="&$A13,Diário!$A$5:$A$400,"<="&$B13)) | J13: =IF(A13="","",IF(H13=0,0,I13/H13)) | K13: =IF(A13="","",IF(I13=0,0,E13*Premissas!$C$5/I13)) | L13: =IF(A13="","",IF(I12=0,"n/d",I13/I12-1))
A14: =IF(B13="","",IF(B13+1>MAX(Diário!$A$5:$A$400),"",B13+1)) | B14: =IF(A14="","",A14+6) | C14: =IF(A14="","",COUNTIFS(Diário!$A$5:$A$400,">="&$A14,Diário!$A$5:$A$400,"<="&$B14)) | D14: =IF($A14="","",SUMIFS(Diário!$B$5:$B$400,Diário!$A$5:$A$400,">="&$A14,Diário!$A$5:$A$400,"<="&$B14)) | E14: =IF($A14="","",SUMIFS(Diário!$E$5:$E$400,Diário!$A$5:$A$400,">="&$A14,Diário!$A$5:$A$400,"<="&$B14)) | F14: =IF($A14="","",SUMIFS(Diário!$D$5:$D$400,Diário!$A$5:$A$400,">="&$A14,Diário!$A$5:$A$400,"<="&$B14)) | G14: =IF($A14="","",SUMIFS(Diário!$C$5:$C$400,Diário!$A$5:$A$400,">="&$A14,Diário!$A$5:$A$400,"<="&$B14)) | H14: =IF(A14="","",SUM(D14:G14)) | I14: =IF($A14="","",SUMIFS(Diário!$G$5:$G$400,Diário!$A$5:$A$400,">="&$A14,Diário!$A$5:$A$400,"<="&$B14)) | J14: =IF(A14="","",IF(H14=0,0,I14/H14)) | K14: =IF(A14="","",IF(I14=0,0,E14*Premissas!$C$5/I14)) | L14: =IF(A14="","",IF(I13=0,"n/d",I14/I13-1))
A15: =IF(B14="","",IF(B14+1>MAX(Diário!$A$5:$A$400),"",B14+1)) | B15: =IF(A15="","",A15+6) | C15: =IF(A15="","",COUNTIFS(Diário!$A$5:$A$400,">="&$A15,Diário!$A$5:$A$400,"<="&$B15)) | D15: =IF($A15="","",SUMIFS(Diário!$B$5:$B$400,Diário!$A$5:$A$400,">="&$A15,Diário!$A$5:$A$400,"<="&$B15)) | E15: =IF($A15="","",SUMIFS(Diário!$E$5:$E$400,Diário!$A$5:$A$400,">="&$A15,Diário!$A$5:$A$400,"<="&$B15)) | F15: =IF($A15="","",SUMIFS(Diário!$D$5:$D$400,Diário!$A$5:$A$400,">="&$A15,Diário!$A$5:$A$400,"<="&$B15)) | G15: =IF($A15="","",SUMIFS(Diário!$C$5:$C$400,Diário!$A$5:$A$400,">="&$A15,Diário!$A$5:$A$400,"<="&$B15)) | H15: =IF(A15="","",SUM(D15:G15)) | I15: =IF($A15="","",SUMIFS(Diário!$G$5:$G$400,Diário!$A$5:$A$400,">="&$A15,Diário!$A$5:$A$400,"<="&$B15)) | J15: =IF(A15="","",IF(H15=0,0,I15/H15)) | K15: =IF(A15="","",IF(I15=0,0,E15*Premissas!$C$5/I15)) | L15: =IF(A15="","",IF(I14=0,"n/d",I15/I14-1))
A16: =IF(B15="","",IF(B15+1>MAX(Diário!$A$5:$A$400),"",B15+1)) | B16: =IF(A16="","",A16+6) | C16: =IF(A16="","",COUNTIFS(Diário!$A$5:$A$400,">="&$A16,Diário!$A$5:$A$400,"<="&$B16)) | D16: =IF($A16="","",SUMIFS(Diário!$B$5:$B$400,Diário!$A$5:$A$400,">="&$A16,Diário!$A$5:$A$400,"<="&$B16)) | E16: =IF($A16="","",SUMIFS(Diário!$E$5:$E$400,Diário!$A$5:$A$400,">="&$A16,Diário!$A$5:$A$400,"<="&$B16)) | F16: =IF($A16="","",SUMIFS(Diário!$D$5:$D$400,Diário!$A$5:$A$400,">="&$A16,Diário!$A$5:$A$400,"<="&$B16)) | G16: =IF($A16="","",SUMIFS(Diário!$C$5:$C$400,Diário!$A$5:$A$400,">="&$A16,Diário!$A$5:$A$400,"<="&$B16)) | H16: =IF(A16="","",SUM(D16:G16)) | I16: =IF($A16="","",SUMIFS(Diário!$G$5:$G$400,Diário!$A$5:$A$400,">="&$A16,Diário!$A$5:$A$400,"<="&$B16)) | J16: =IF(A16="","",IF(H16=0,0,I16/H16)) | K16: =IF(A16="","",IF(I16=0,0,E16*Premissas!$C$5/I16)) | L16: =IF(A16="","",IF(I15=0,"n/d",I16/I15-1))
A17: =IF(B16="","",IF(B16+1>MAX(Diário!$A$5:$A$400),"",B16+1)) | B17: =IF(A17="","",A17+6) | C17: =IF(A17="","",COUNTIFS(Diário!$A$5:$A$400,">="&$A17,Diário!$A$5:$A$400,"<="&$B17)) | D17: =IF($A17="","",SUMIFS(Diário!$B$5:$B$400,Diário!$A$5:$A$400,">="&$A17,Diário!$A$5:$A$400,"<="&$B17)) | E17: =IF($A17="","",SUMIFS(Diário!$E$5:$E$400,Diário!$A$5:$A$400,">="&$A17,Diário!$A$5:$A$400,"<="&$B17)) | F17: =IF($A17="","",SUMIFS(Diário!$D$5:$D$400,Diário!$A$5:$A$400,">="&$A17,Diário!$A$5:$A$400,"<="&$B17)) | G17: =IF($A17="","",SUMIFS(Diário!$C$5:$C$400,Diário!$A$5:$A$400,">="&$A17,Diário!$A$5:$A$400,"<="&$B17)) | H17: =IF(A17="","",SUM(D17:G17)) | I17: =IF($A17="","",SUMIFS(Diário!$G$5:$G$400,Diário!$A$5:$A$400,">="&$A17,Diário!$A$5:$A$400,"<="&$B17)) | J17: =IF(A17="","",IF(H17=0,0,I17/H17)) | K17: =IF(A17="","",IF(I17=0,0,E17*Premissas!$C$5/I17)) | L17: =IF(A17="","",IF(I16=0,"n/d",I17/I16-1))
... A64: =IF(B63="","",IF(B63+1>MAX(Diário!$A$5:$A$400),"",B63+1)) | B64: =IF(A64="","",A64+6) | C64: =IF(A64="","",COUNTIFS(Diário!$A$5:$A$400,">="&$A64,Diário!$A$5:$A$400,"<="&$B64)) | D64: =IF($A64="","",SUMIFS(Diário!$B$5:$B$400,Diário!$A$5:$A$400,">="&$A64,Diário!$A$5:$A$400,"<="&$B64)) | E64: =IF($A64="","",SUMIFS(Diário!$E$5:$E$400,Diário!$A$5:$A$400,">="&$A64,Diário!$A$5:$A$400,"<="&$B64)) | F64: =IF($A64="","",SUMIFS(Diário!$D$5:$D$400,Diário!$A$5:$A$400,">="&$A64,Diário!$A$5:$A$400,"<="&$B64)) | G64: =IF($A64="","",SUMIFS(Diário!$C$5:$C$400,Diário!$A$5:$A$400,">="&$A64,Diário!$A$5:$A$400,"<="&$B64)) | H64: =IF(A64="","",SUM(D64:G64)) | I64: =IF($A64="","",SUMIFS(Diário!$G$5:$G$400,Diário!$A$5:$A$400,">="&$A64,Diário!$A$5:$A$400,"<="&$B64)) | J64: =IF(A64="","",IF(H64=0,0,I64/H64)) | K64: =IF(A64="","",IF(I64=0,0,E64*Premissas!$C$5/I64)) | L64: =IF(A64="","",IF(I63=0,"n/d",I64/I63-1))

Sheet Mensal
A1: Relatório mensal
A4: Mês | B4: Dias com dados | C4: Utilidade | D4: Marketing Lite | E4: Marketing | F4: Autenticação | G4: Total de mensagens | H4: Custo Utilidade (R$) | I4: Custo Marketing Lite (R$) | J4: Custo Marketing (R$) | K4: Custo Autenticação (R$) | L4: Custo total (R$) | M4: Custo médio por mensagem (R$) | N4: % do custo em Marketing Lite | O4: Variação do custo vs. mês anterior
A5: =IF(COUNT(Diário!$H$5:$H$400)=0,"",MIN(Diário!$H$5:$H$400)) -> 46296 | B5: =IF(A5="","",COUNTIFS(Diário!$H$5:$H$400,A5)) -> 13 | C5: =IF($A5="","",SUMIFS(Diário!$B$5:$B$400,Diário!$H$5:$H$400,$A5)) -> 160207 | D5: =IF($A5="","",SUMIFS(Diário!$E$5:$E$400,Diário!$H$5:$H$400,$A5)) -> 10984 | E5: =IF($A5="","",SUMIFS(Diário!$D$5:$D$400,Diário!$H$5:$H$400,$A5)) -> 0 | F5: =IF($A5="","",SUMIFS(Diário!$C$5:$C$400,Diário!$H$5:$H$400,$A5)) -> 0 | G5: =IF(A5="","",SUM(C5:F5)) -> 171191 | H5: =IF(A5="","",C5*Premissas!$C$4) -> 14418.63 | I5: =IF(A5="","",D5*Premissas!$C$5) -> 5931.36 | J5: =IF(A5="","",E5*Premissas!$C$6) -> 0 | K5: =IF(A5="","",F5*Premissas!$C$7) -> 0 | L5: =IF(A5="","",SUM(H5:K5)) -> 20349.99 | M5: =IF(A5="","",IF(G5=0,0,L5/G5)) -> 0.11887301 | N5: =IF(A5="","",IF(L5=0,0,I5/L5)) -> 0.29146747 | O5: =IF(A5="","","n/d") -> n/d
A6: =IF(A5="","",IF(EDATE(A5,1)>MAX(Diário!$A$5:$A$400),"",EDATE(A5,1))) | B6: =IF(A6="","",COUNTIFS(Diário!$H$5:$H$400,A6)) | C6: =IF($A6="","",SUMIFS(Diário!$B$5:$B$400,Diário!$H$5:$H$400,$A6)) | D6: =IF($A6="","",SUMIFS(Diário!$E$5:$E$400,Diário!$H$5:$H$400,$A6)) | E6: =IF($A6="","",SUMIFS(Diário!$D$5:$D$400,Diário!$H$5:$H$400,$A6)) | F6: =IF($A6="","",SUMIFS(Diário!$C$5:$C$400,Diário!$H$5:$H$400,$A6)) | G6: =IF(A6="","",SUM(C6:F6)) | H6: =IF(A6="","",C6*Premissas!$C$4) | I6: =IF(A6="","",D6*Premissas!$C$5) | J6: =IF(A6="","",E6*Premissas!$C$6) | K6: =IF(A6="","",F6*Premissas!$C$7) | L6: =IF(A6="","",SUM(H6:K6)) | M6: =IF(A6="","",IF(G6=0,0,L6/G6)) | N6: =IF(A6="","",IF(L6=0,0,I6/L6)) | O6: =IF(A6="","",IF(L5=0,"n/d",L6/L5-1))
A7: =IF(A6="","",IF(EDATE(A6,1)>MAX(Diário!$A$5:$A$400),"",EDATE(A6,1))) | B7: =IF(A7="","",COUNTIFS(Diário!$H$5:$H$400,A7)) | C7: =IF($A7="","",SUMIFS(Diário!$B$5:$B$400,Diário!$H$5:$H$400,$A7)) | D7: =IF($A7="","",SUMIFS(Diário!$E$5:$E$400,Diário!$H$5:$H$400,$A7)) | E7: =IF($A7="","",SUMIFS(Diário!$D$5:$D$400,Diário!$H$5:$H$400,$A7)) | F7: =IF($A7="","",SUMIFS(Diário!$C$5:$C$400,Diário!$H$5:$H$400,$A7)) | G7: =IF(A7="","",SUM(C7:F7)) | H7: =IF(A7="","",C7*Premissas!$C$4) | I7: =IF(A7="","",D7*Premissas!$C$5) | J7: =IF(A7="","",E7*Premissas!$C$6) | K7: =IF(A7="","",F7*Premissas!$C$7) | L7: =IF(A7="","",SUM(H7:K7)) | M7: =IF(A7="","",IF(G7=0,0,L7/G7)) | N7: =IF(A7="","",IF(L7=0,0,I7/L7)) | O7: =IF(A7="","",IF(L6=0,"n/d",L7/L6-1))
A8: =IF(A7="","",IF(EDATE(A7,1)>MAX(Diário!$A$5:$A$400),"",EDATE(A7,1))) | B8: =IF(A8="","",COUNTIFS(Diário!$H$5:$H$400,A8)) | C8: =IF($A8="","",SUMIFS(Diário!$B$5:$B$400,Diário!$H$5:$H$400,$A8)) | D8: =IF($A8="","",SUMIFS(Diário!$E$5:$E$400,Diário!$H$5:$H$400,$A8)) | E8: =IF($A8="","",SUMIFS(Diário!$D$5:$D$400,Diário!$H$5:$H$400,$A8)) | F8: =IF($A8="","",SUMIFS(Diário!$C$5:$C$400,Diário!$H$5:$H$400,$A8)) | G8: =IF(A8="","",SUM(C8:F8)) | H8: =IF(A8="","",C8*Premissas!$C$4) | I8: =IF(A8="","",D8*Premissas!$C$5) | J8: =IF(A8="","",E8*Premissas!$C$6) | K8: =IF(A8="","",F8*Premissas!$C$7) | L8: =IF(A8="","",SUM(H8:K8)) | M8: =IF(A8="","",IF(G8=0,0,L8/G8)) | N8: =IF(A8="","",IF(L8=0,0,I8/L8)) | O8: =IF(A8="","",IF(L7=0,"n/d",L8/L7-1))
A9: =IF(A8="","",IF(EDATE(A8,1)>MAX(Diário!$A$5:$A$400),"",EDATE(A8,1))) | B9: =IF(A9="","",COUNTIFS(Diário!$H$5:$H$400,A9)) | C9: =IF($A9="","",SUMIFS(Diário!$B$5:$B$400,Diário!$H$5:$H$400,$A9)) | D9: =IF($A9="","",SUMIFS(Diário!$E$5:$E$400,Diário!$H$5:$H$400,$A9)) | E9: =IF($A9="","",SUMIFS(Diário!$D$5:$D$400,Diário!$H$5:$H$400,$A9)) | F9: =IF($A9="","",SUMIFS(Diário!$C$5:$C$400,Diário!$H$5:$H$400,$A9)) | G9: =IF(A9="","",SUM(C9:F9)) | H9: =IF(A9="","",C9*Premissas!$C$4) | I9: =IF(A9="","",D9*Premissas!$C$5) | J9: =IF(A9="","",E9*Premissas!$C$6) | K9: =IF(A9="","",F9*Premissas!$C$7) | L9: =IF(A9="","",SUM(H9:K9)) | M9: =IF(A9="","",IF(G9=0,0,L9/G9)) | N9: =IF(A9="","",IF(L9=0,0,I9/L9)) | O9: =IF(A9="","",IF(L8=0,"n/d",L9/L8-1))
A10: =IF(A9="","",IF(EDATE(A9,1)>MAX(Diário!$A$5:$A$400),"",EDATE(A9,1))) | B10: =IF(A10="","",COUNTIFS(Diário!$H$5:$H$400,A10)) | C10: =IF($A10="","",SUMIFS(Diário!$B$5:$B$400,Diário!$H$5:$H$400,$A10)) | D10: =IF($A10="","",SUMIFS(Diário!$E$5:$E$400,Diário!$H$5:$H$400,$A10)) | E10: =IF($A10="","",SUMIFS(Diário!$D$5:$D$400,Diário!$H$5:$H$400,$A10)) | F10: =IF($A10="","",SUMIFS(Diário!$C$5:$C$400,Diário!$H$5:$H$400,$A10)) | G10: =IF(A10="","",SUM(C10:F10)) | H10: =IF(A10="","",C10*Premissas!$C$4) | I10: =IF(A10="","",D10*Premissas!$C$5) | J10: =IF(A10="","",E10*Premissas!$C$6) | K10: =IF(A10="","",F10*Premissas!$C$7) | L10: =IF(A10="","",SUM(H10:K10)) | M10: =IF(A10="","",IF(G10=0,0,L10/G10)) | N10: =IF(A10="","",IF(L10=0,0,I10/L10)) | O10: =IF(A10="","",IF(L9=0,"n/d",L10/L9-1))
A11: =IF(A10="","",IF(EDATE(A10,1)>MAX(Diário!$A$5:$A$400),"",EDATE(A10,1))) | B11: =IF(A11="","",COUNTIFS(Diário!$H$5:$H$400,A11)) | C11: =IF($A11="","",SUMIFS(Diário!$B$5:$B$400,Diário!$H$5:$H$400,$A11)) | D11: =IF($A11="","",SUMIFS(Diário!$E$5:$E$400,Diário!$H$5:$H$400,$A11)) | E11: =IF($A11="","",SUMIFS(Diário!$D$5:$D$400,Diário!$H$5:$H$400,$A11)) | F11: =IF($A11="","",SUMIFS(Diário!$C$5:$C$400,Diário!$H$5:$H$400,$A11)) | G11: =IF(A11="","",SUM(C11:F11)) | H11: =IF(A11="","",C11*Premissas!$C$4) | I11: =IF(A11="","",D11*Premissas!$C$5) | J11: =IF(A11="","",E11*Premissas!$C$6) | K11: =IF(A11="","",F11*Premissas!$C$7) | L11: =IF(A11="","",SUM(H11:K11)) | M11: =IF(A11="","",IF(G11=0,0,L11/G11)) | N11: =IF(A11="","",IF(L11=0,0,I11/L11)) | O11: =IF(A11="","",IF(L10=0,"n/d",L11/L10-1))
A12: =IF(A11="","",IF(EDATE(A11,1)>MAX(Diário!$A$5:$A$400),"",EDATE(A11,1))) | B12: =IF(A12="","",COUNTIFS(Diário!$H$5:$H$400,A12)) | C12: =IF($A12="","",SUMIFS(Diário!$B$5:$B$400,Diário!$H$5:$H$400,$A12)) | D12: =IF($A12="","",SUMIFS(Diário!$E$5:$E$400,Diário!$H$5:$H$400,$A12)) | E12: =IF($A12="","",SUMIFS(Diário!$D$5:$D$400,Diário!$H$5:$H$400,$A12)) | F12: =IF($A12="","",SUMIFS(Diário!$C$5:$C$400,Diário!$H$5:$H$400,$A12)) | G12: =IF(A12="","",SUM(C12:F12)) | H12: =IF(A12="","",C12*Premissas!$C$4) | I12: =IF(A12="","",D12*Premissas!$C$5) | J12: =IF(A12="","",E12*Premissas!$C$6) | K12: =IF(A12="","",F12*Premissas!$C$7) | L12: =IF(A12="","",SUM(H12:K12)) | M12: =IF(A12="","",IF(G12=0,0,L12/G12)) | N12: =IF(A12="","",IF(L12=0,0,I12/L12)) | O12: =IF(A12="","",IF(L11=0,"n/d",L12/L11-1))
A13: =IF(A12="","",IF(EDATE(A12,1)>MAX(Diário!$A$5:$A$400),"",EDATE(A12,1))) | B13: =IF(A13="","",COUNTIFS(Diário!$H$5:$H$400,A13)) | C13: =IF($A13="","",SUMIFS(Diário!$B$5:$B$400,Diário!$H$5:$H$400,$A13)) | D13: =IF($A13="","",SUMIFS(Diário!$E$5:$E$400,Diário!$H$5:$H$400,$A13)) | E13: =IF($A13="","",SUMIFS(Diário!$D$5:$D$400,Diário!$H$5:$H$400,$A13)) | F13: =IF($A13="","",SUMIFS(Diário!$C$5:$C$400,Diário!$H$5:$H$400,$A13)) | G13: =IF(A13="","",SUM(C13:F13)) | H13: =IF(A13="","",C13*Premissas!$C$4) | I13: =IF(A13="","",D13*Premissas!$C$5) | J13: =IF(A13="","",E13*Premissas!$C$6) | K13: =IF(A13="","",F13*Premissas!$C$7) | L13: =IF(A13="","",SUM(H13:K13)) | M13: =IF(A13="","",IF(G13=0,0,L13/G13)) | N13: =IF(A13="","",IF(L13=0,0,I13/L13)) | O13: =IF(A13="","",IF(L12=0,"n/d",L13/L12-1))
A14: =IF(A13="","",IF(EDATE(A13,1)>MAX(Diário!$A$5:$A$400),"",EDATE(A13,1))) | B14: =IF(A14="","",COUNTIFS(Diário!$H$5:$H$400,A14)) | C14: =IF($A14="","",SUMIFS(Diário!$B$5:$B$400,Diário!$H$5:$H$400,$A14)) | D14: =IF($A14="","",SUMIFS(Diário!$E$5:$E$400,Diário!$H$5:$H$400,$A14)) | E14: =IF($A14="","",SUMIFS(Diário!$D$5:$D$400,Diário!$H$5:$H$400,$A14)) | F14: =IF($A14="","",SUMIFS(Diário!$C$5:$C$400,Diário!$H$5:$H$400,$A14)) | G14: =IF(A14="","",SUM(C14:F14)) | H14: =IF(A14="","",C14*Premissas!$C$4) | I14: =IF(A14="","",D14*Premissas!$C$5) | J14: =IF(A14="","",E14*Premissas!$C$6) | K14: =IF(A14="","",F14*Premissas!$C$7) | L14: =IF(A14="","",SUM(H14:K14)) | M14: =IF(A14="","",IF(G14=0,0,L14/G14)) | N14: =IF(A14="","",IF(L14=0,0,I14/L14)) | O14: =IF(A14="","",IF(L13=0,"n/d",L14/L13-1))
A15: =IF(A14="","",IF(EDATE(A14,1)>MAX(Diário!$A$5:$A$400),"",EDATE(A14,1))) | B15: =IF(A15="","",COUNTIFS(Diário!$H$5:$H$400,A15)) | C15: =IF($A15="","",SUMIFS(Diário!$B$5:$B$400,Diário!$H$5:$H$400,$A15)) | D15: =IF($A15="","",SUMIFS(Diário!$E$5:$E$400,Diário!$H$5:$H$400,$A15)) | E15: =IF($A15="","",SUMIFS(Diário!$D$5:$D$400,Diário!$H$5:$H$400,$A15)) | F15: =IF($A15="","",SUMIFS(Diário!$C$5:$C$400,Diário!$H$5:$H$400,$A15)) | G15: =IF(A15="","",SUM(C15:F15)) | H15: =IF(A15="","",C15*Premissas!$C$4) | I15: =IF(A15="","",D15*Premissas!$C$5) | J15: =IF(A15="","",E15*Premissas!$C$6) | K15: =IF(A15="","",F15*Premissas!$C$7) | L15: =IF(A15="","",SUM(H15:K15)) | M15: =IF(A15="","",IF(G15=0,0,L15/G15)) | N15: =IF(A15="","",IF(L15=0,0,I15/L15)) | O15: =IF(A15="","",IF(L14=0,"n/d",L15/L14-1))
A16: =IF(A15="","",IF(EDATE(A15,1)>MAX(Diário!$A$5:$A$400),"",EDATE(A15,1))) | B16: =IF(A16="","",COUNTIFS(Diário!$H$5:$H$400,A16)) | C16: =IF($A16="","",SUMIFS(Diário!$B$5:$B$400,Diário!$H$5:$H$400,$A16)) | D16: =IF($A16="","",SUMIFS(Diário!$E$5:$E$400,Diário!$H$5:$H$400,$A16)) | E16: =IF($A16="","",SUMIFS(Diário!$D$5:$D$400,Diário!$H$5:$H$400,$A16)) | F16: =IF($A16="","",SUMIFS(Diário!$C$5:$C$400,Diário!$H$5:$H$400,$A16)) | G16: =IF(A16="","",SUM(C16:F16)) | H16: =IF(A16="","",C16*Premissas!$C$4) | I16: =IF(A16="","",D16*Premissas!$C$5) | J16: =IF(A16="","",E16*Premissas!$C$6) | K16: =IF(A16="","",F16*Premissas!$C$7) | L16: =IF(A16="","",SUM(H16:K16)) | M16: =IF(A16="","",IF(G16=0,0,L16/G16)) | N16: =IF(A16="","",IF(L16=0,0,I16/L16)) | O16: =IF(A16="","",IF(L15=0,"n/d",L16/L15-1))
A17: =IF(A16="","",IF(EDATE(A16,1)>MAX(Diário!$A$5:$A$400),"",EDATE(A16,1))) | B17: =IF(A17="","",COUNTIFS(Diário!$H$5:$H$400,A17)) | C17: =IF($A17="","",SUMIFS(Diário!$B$5:$B$400,Diário!$H$5:$H$400,$A17)) | D17: =IF($A17="","",SUMIFS(Diário!$E$5:$E$400,Diário!$H$5:$H$400,$A17)) | E17: =IF($A17="","",SUMIFS(Diário!$D$5:$D$400,Diário!$H$5:$H$400,$A17)) | F17: =IF($A17="","",SUMIFS(Diário!$C$5:$C$400,Diário!$H$5:$H$400,$A17)) | G17: =IF(A17="","",SUM(C17:F17)) | H17: =IF(A17="","",C17*Premissas!$C$4) | I17: =IF(A17="","",D17*Premissas!$C$5) | J17: =IF(A17="","",E17*Premissas!$C$6) | K17: =IF(A17="","",F17*Premissas!$C$7) | L17: =IF(A17="","",SUM(H17:K17)) | M17: =IF(A17="","",IF(G17=0,0,L17/G17)) | N17: =IF(A17="","",IF(L17=0,0,I17/L17)) | O17: =IF(A17="","",IF(L16=0,"n/d",L17/L16-1))
... A40: =IF(A39="","",IF(EDATE(A39,1)>MAX(Diário!$A$5:$A$400),"",EDATE(A39,1))) | B40: =IF(A40="","",COUNTIFS(Diário!$H$5:$H$400,A40)) | C40: =IF($A40="","",SUMIFS(Diário!$B$5:$B$400,Diário!$H$5:$H$400,$A40)) | D40: =IF($A40="","",SUMIFS(Diário!$E$5:$E$400,Diário!$H$5:$H$400,$A40)) | E40: =IF($A40="","",SUMIFS(Diário!$D$5:$D$400,Diário!$H$5:$H$400,$A40)) | F40: =IF($A40="","",SUMIFS(Diário!$C$5:$C$400,Diário!$H$5:$H$400,$A40)) | G40: =IF(A40="","",SUM(C40:F40)) | H40: =IF(A40="","",C40*Premissas!$C$4) | I40: =IF(A40="","",D40*Premissas!$C$5) | J40: =IF(A40="","",E40*Premissas!$C$6) | K40: =IF(A40="","",F40*Premissas!$C$7) | L40: =IF(A40="","",SUM(H40:K40)) | M40: =IF(A40="","",IF(G40=0,0,L40/G40)) | N40: =IF(A40="","",IF(L40=0,0,I40/L40)) | O40: =IF(A40="","",IF(L39=0,"n/d",L40/L39-1))

Sheet Consolidado
A1: Consolidado de disparos WhatsApp: volume e custo estimado por mês
A2: Disparos = mensagens iniciadas pela empresa (Utilidade + Marketing Lite + Marketing + Autenticação). Jan/25 a set/26 vêm da aba Histórico diário; out/26 em diante vêm da aba Diário. O custo usa as tarifas da aba Tarifas por mês (meses de jan/25 a set/26) e de Premissas (demais meses). Linha em amarelo claro = mês parcial.
A4: Último mês completo | B4: =_xlfn.MAXIFS($A$14:$A$61,$S$14:$S$61,1) -> 46266
A5: Período | B5: Meses | C5: Disparos | D5: Custo estimado (R$) | E5: Custo médio por disparo (R$) | F5: Custo médio por mês (R$)
A6: ="Ano "&(YEAR($B$4)-1)&" completo" -> Ano 2025 completo | B6: =COUNTIFS($A$14:$A$61,">="&DATE(YEAR($B$4)-1,1,1),$A$14:$A$61,"<="&DATE(YEAR($B$4)-1,12,1),$S$14:$S$61,1) -> 12 | C6: =SUMIFS($G$14:$G$61,$A$14:$A$61,">="&DATE(YEAR($B$4)-1,1,1),$A$14:$A$61,"<="&DATE(YEAR($B$4)-1,12,1),$S$14:$S$61,1) -> 645377 | D6: =SUMIFS($L$14:$L$61,$A$14:$A$61,">="&DATE(YEAR($B$4)-1,1,1),$A$14:$A$61,"<="&DATE(YEAR($B$4)-1,12,1),$S$14:$S$61,1) -> 378671.76 | E6: =IF(C6=0,0,D6/C6) -> 0.58674505 | F6: =IF(B6=0,0,D6/B6) -> 31555.98
A7: ="Ano "&YEAR($B$4)&" (jan a "&CHOOSE(MONTH($B$4),"jan","fev","mar","abr","mai","jun","jul","ago","set","out","nov","dez")&")" -> Ano 2026 (jan a set) | B7: =COUNTIFS($A$14:$A$61,">="&DATE(YEAR($B$4),1,1),$A$14:$A$61,"<="&$B$4,$S$14:$S$61,1) -> 9 | C7: =SUMIFS($G$14:$G$61,$A$14:$A$61,">="&DATE(YEAR($B$4),1,1),$A$14:$A$61,"<="&$B$4,$S$14:$S$61,1) -> 969444 | D7: =SUMIFS($L$14:$L$61,$A$14:$A$61,">="&DATE(YEAR($B$4),1,1),$A$14:$A$61,"<="&$B$4,$S$14:$S$61,1) -> 446794.71 | E7: =IF(C7=0,0,D7/C7) -> 0.46087728 | F7: =IF(B7=0,0,D7/B7) -> 49643.857
A8: ="Ano "&(YEAR($B$4)-1)&" (jan a "&CHOOSE(MONTH($B$4),"jan","fev","mar","abr","mai","jun","jul","ago","set","out","nov","dez")&")" -> Ano 2025 (jan a set) | B8: =COUNTIFS($A$14:$A$61,">="&DATE(YEAR($B$4)-1,1,1),$A$14:$A$61,"<="&EDATE($B$4,-12),$S$14:$S$61,1) -> 9 | C8: =SUMIFS($G$14:$G$61,$A$14:$A$61,">="&DATE(YEAR($B$4)-1,1,1),$A$14:$A$61,"<="&EDATE($B$4,-12),$S$14:$S$61,1) -> 518169 | D8: =SUMIFS($L$14:$L$61,$A$14:$A$61,">="&DATE(YEAR($B$4)-1,1,1),$A$14:$A$61,"<="&EDATE($B$4,-12),$S$14:$S$61,1) -> 309978.72 | E8: =IF(C8=0,0,D8/C8) -> 0.59821935 | F8: =IF(B8=0,0,D8/B8) -> 34442.08
A9: Variação vs. mesmo período do ano anterior | C9: =IF(C8=0,"n/d",C7/C8-1) -> 0.87090312 | D9: =IF(D8=0,"n/d",D7/D8-1) -> 0.4413722 | E9: =IF(E8=0,"n/d",E7/E8-1) -> -0.2295848 | F9: =IF(F8=0,"n/d",F7/F8-1) -> 0.4413722
A10: Acumulado desde jan/25 (inclui mês parcial) | B10: =COUNT($A$14:$A$61) -> 22 | C10: =SUM($G$14:$G$61) -> 1786012 | D10: =SUM($L$14:$L$61) -> 845816.46 | E10: =IF(C10=0,0,D10/C10) -> 0.47357826 | F10: =IF(B10=0,0,D10/B10) -> 38446.203
A11: Meses parciais ficam fora das linhas de período (veja Dias com dados) e entram só no acumulado.
C12: Disparos | H12: Custo estimado (R$)
A13: Mês | B13: Dias com dados | C13: Utilidade | D13: Marketing Lite | E13: Marketing | F13: Autenticação | G13: Total de disparos | H13: Utilidade | I13: Marketing Lite | J13: Marketing | K13: Autenticação | L13: Custo total | M13: Custo médio por disparo (R$) | N13: Média diária de disparos | O13: Pico diário (disparos) | P13: Dia de pico | Q13: Var. do custo vs. mês anterior | R13: Var. do custo vs. mesmo mês do ano anterior | S13: Mês completo (1 = sim)
A14: =MIN('Histórico diário'!$G$5:$G$642) -> 45658 | B14: =IF(A14="","",COUNTIFS('Histórico diário'!$G$5:$G$642,A14)+COUNTIFS(Diário!$H$5:$H$400,A14)) -> 31 | C14: =IF($A14="","",SUMIFS('Histórico diário'!$B$5:$B$642,'Histórico diário'!$G$5:$G$642,$A14)+SUMIFS(Diário!$B$5:$B$400,Diário!$H$5:$H$400,$A14)) -> 0 | D14: =IF($A14="","",SUMIFS('Histórico diário'!$E$5:$E$642,'Histórico diário'!$G$5:$G$642,$A14)+SUMIFS(Diário!$E$5:$E$400,Diário!$H$5:$H$400,$A14)) -> 0 | E14: =IF($A14="","",SUMIFS('Histórico diário'!$D$5:$D$642,'Histórico diário'!$G$5:$G$642,$A14)+SUMIFS(Diário!$D$5:$D$400,Diário!$H$5:$H$400,$A14)) -> 31537 | F14: =IF($A14="","",SUMIFS('Histórico diário'!$C$5:$C$642,'Histórico diário'!$G$5:$G$642,$A14)+SUMIFS(Diário!$C$5:$C$400,Diário!$H$5:$H$400,$A14)) -> 0 | G14: =IF(A14="","",SUM(C14:F14)) -> 31537 | H14: =IF($A14="","",C14*IFERROR(INDEX('Tarifas por mês'!$B$5:$B$25,MATCH($A14,'Tarifas por mês'!$A$5:$A$25,0)),Premissas!$C$4)) -> 0 | I14: =IF($A14="","",D14*IFERROR(INDEX('Tarifas por mês'!$C$5:$C$25,MATCH($A14,'Tarifas por mês'!$A$5:$A$25,0)),Premissas!$C$5)) -> 0 | J14: =IF($A14="","",E14*IFERROR(INDEX('Tarifas por mês'!$D$5:$D$25,MATCH($A14,'Tarifas por mês'!$A$5:$A$25,0)),Premissas!$C$6)) -> 18922.2 | K14: =IF($A14="","",F14*IFERROR(INDEX('Tarifas por mês'!$E$5:$E$25,MATCH($A14,'Tarifas por mês'!$A$5:$A$25,0)),Premissas!$C$7)) -> 0 | L14: =IF(A14="","",SUM(H14:K14)) -> 18922.2 | M14: =IF(A14="","",IF(G14=0,0,L14/G14)) -> 0.6 | N14: =IF(A14="","",IF(B14=0,0,G14/B14)) -> 1017.3226 | O14: =IF(A14="","",MAX(_xlfn.MAXIFS('Histórico diário'!$F$5:$F$642,'Histórico diário'!$G$5:$G$642,$A14),_xlfn.MAXIFS(Diário!$F$5:$F$400,Diário!$H$5:$H$400,$A14))) -> 10198 | P14: =IF($A14="","",IF(O14=0,"",IF(_xlfn.MAXIFS('Histórico diário'!$F$5:$F$642,'Histórico diário'!$G$5:$G$642,$A14)>=_xlfn.MAXIFS(Diário!$F$5:$F$400,Diário!$H$5:$H$400,$A14),SUMPRODUCT(MAX(('Histórico diário'!$G$5:$G$642=$A14)*('Histórico diário'!$F$5:$F$642=O14)*'Histórico diário'!$A$5:$A$642)),SUMPRODUCT(MAX((Diário!$H$5:$H$400=$A14)*(Diário!$F$5:$F$400=O14)*Diário!$A$5:$A$400))))) -> 45684 | Q14: =IF(A14="","","n/d") -> n/d | R14: =IF(A14="","","n/d") -> n/d | S14: =IF(A14="","",IF(B14=DAY(EOMONTH(A14,0)),1,0)) -> 1
A15: =IF(A14="","",IF(EDATE(A14,1)>MAX(MAX('Histórico diário'!$A$5:$A$642),MAX(Diário!$A$5:$A$400)),"",EDATE(A14,1))) -> 45689 | B15: =IF(A15="","",COUNTIFS('Histórico diário'!$G$5:$G$642,A15)+COUNTIFS(Diário!$H$5:$H$400,A15)) -> 28 | C15: =IF($A15="","",SUMIFS('Histórico diário'!$B$5:$B$642,'Histórico diário'!$G$5:$G$642,$A15)+SUMIFS(Diário!$B$5:$B$400,Diário!$H$5:$H$400,$A15)) -> 0 | D15: =IF($A15="","",SUMIFS('Histórico diário'!$E$5:$E$642,'Histórico diário'!$G$5:$G$642,$A15)+SUMIFS(Diário!$E$5:$E$400,Diário!$H$5:$H$400,$A15)) -> 0 | E15: =IF($A15="","",SUMIFS('Histórico diário'!$D$5:$D$642,'Histórico diário'!$G$5:$G$642,$A15)+SUMIFS(Diário!$D$5:$D$400,Diário!$H$5:$H$400,$A15)) -> 35732 | F15: =IF($A15="","",SUMIFS('Histórico diário'!$C$5:$C$642,'Histórico diário'!$G$5:$G$642,$A15)+SUMIFS(Diário!$C$5:$C$400,Diário!$H$5:$H$400,$A15)) -> 0 | G15: =IF(A15="","",SUM(C15:F15)) -> 35732 | H15: =IF($A15="","",C15*IFERROR(INDEX('Tarifas por mês'!$B$5:$B$25,MATCH($A15,'Tarifas por mês'!$A$5:$A$25,0)),Premissas!$C$4)) -> 0 | I15: =IF($A15="","",D15*IFERROR(INDEX('Tarifas por mês'!$C$5:$C$25,MATCH($A15,'Tarifas por mês'!$A$5:$A$25,0)),Premissas!$C$5)) -> 0 | J15: =IF($A15="","",E15*IFERROR(INDEX('Tarifas por mês'!$D$5:$D$25,MATCH($A15,'Tarifas por mês'!$A$5:$A$25,0)),Premissas!$C$6)) -> 21439.2 | K15: =IF($A15="","",F15*IFERROR(INDEX('Tarifas por mês'!$E$5:$E$25,MATCH($A15,'Tarifas por mês'!$A$5:$A$25,0)),Premissas!$C$7)) -> 0 | L15: =IF(A15="","",SUM(H15:K15)) -> 21439.2 | M15: =IF(A15="","",IF(G15=0,0,L15/G15)) -> 0.6 | N15: =IF(A15="","",IF(B15=0,0,G15/B15)) -> 1276.1429 | O15: =IF(A15="","",MAX(_xlfn.MAXIFS('Histórico diário'!$F$5:$F$642,'Histórico diário'!$G$5:$G$642,$A15),_xlfn.MAXIFS(Diário!$F$5:$F$400,Diário!$H$5:$H$400,$A15))) -> 8271 | P15: =IF($A15="","",IF(O15=0,"",IF(_xlfn.MAXIFS('Histórico diário'!$F$5:$F$642,'Histórico diário'!$G$5:$G$642,$A15)>=_xlfn.MAXIFS(Diário!$F$5:$F$400,Diário!$H$5:$H$400,$A15),SUMPRODUCT(MAX(('Histórico diário'!$G$5:$G$642=$A15)*('Histórico diário'!$F$5:$F$642=O15)*'Histórico diário'!$A$5:$A$642)),SUMPRODUCT(MAX((Diário!$H$5:$H$400=$A15)*(Diário!$F$5:$F$400=O15)*Diário!$A$5:$A$400))))) -> 45714 | Q15: =IF(A15="","",IF(S15=0,"parcial",IF(L14=0,"n/d",L15/L14-1))) -> 0.13301836 | R15: =IF(A15="","","n/d") -> n/d | S15: =IF(A15="","",IF(B15=DAY(EOMONTH(A15,0)),1,0)) -> 1
A16: =IF(A15="","",IF(EDATE(A15,1)>MAX(MAX('Histórico diário'!$A$5:$A$642),MAX(Diário!$A$5:$A$400)),"",EDATE(A15,1))) -> 45717 | B16: =IF(A16="","",COUNTIFS('Histórico diário'!$G$5:$G$642,A16)+COUNTIFS(Diário!$H$5:$H$400,A16)) -> 31 | C16: =IF($A16="","",SUMIFS('Histórico diário'!$B$5:$B$642,'Histórico diário'!$G$5:$G$642,$A16)+SUMIFS(Diário!$B$5:$B$400,Diário!$H$5:$H$400,$A16)) -> 0 | D16: =IF($A16="","",SUMIFS('Histórico diário'!$E$5:$E$642,'Histórico diário'!$G$5:$G$642,$A16)+SUMIFS(Diário!$E$5:$E$400,Diário!$H$5:$H$400,$A16)) -> 0 | E16: =IF($A16="","",SUMIFS('Histórico diário'!$D$5:$D$642,'Histórico diário'!$G$5:$G$642,$A16)+SUMIFS(Diário!$D$5:$D$400,Diário!$H$5:$H$400,$A16)) -> 56910 | F16: =IF($A16="","",SUMIFS('Histórico diário'!$C$5:$C$642,'Histórico diário'!$G$5:$G$642,$A16)+SUMIFS(Diário!$C$5:$C$400,Diário!$H$5:$H$400,$A16)) -> 0 | G16: =IF(A16="","",SUM(C16:F16)) -> 56910 | H16: =IF($A16="","",C16*IFERROR(INDEX('Tarifas por mês'!$B$5:$B$25,MATCH($A16,'Tarifas por mês'!$A$5:$A$25,0)),Premissas!$C$4)) -> 0 | I16: =IF($A16="","",D16*IFERROR(INDEX('Tarifas por mês'!$C$5:$C$25,MATCH($A16,'Tarifas por mês'!$A$5:$A$25,0)),Premissas!$C$5)) -> 0 | J16: =IF($A16="","",E16*IFERROR(INDEX('Tarifas por mês'!$D$5:$D$25,MATCH($A16,'Tarifas por mês'!$A$5:$A$25,0)),Premissas!$C$6)) -> 34146 | K16: =IF($A16="","",F16*IFERROR(INDEX('Tarifas por mês'!$E$5:$E$25,MATCH($A16,'Tarifas por mês'!$A$5:$A$25,0)),Premissas!$C$7)) -> 0 | L16: =IF(A16="","",SUM(H16:K16)) -> 34146 | M16: =IF(A16="","",IF(G16=0,0,L16/G16)) -> 0.6 | N16: =IF(A16="","",IF(B16=0,0,G16/B16)) -> 1835.8065 | O16: =IF(A16="","",MAX(_xlfn.MAXIFS('Histórico diário'!$F$5:$F$642,'Histórico diário'!$G$5:$G$642,$A16),_xlfn.MAXIFS(Diário!$F$5:$F$400,Diário!$H$5:$H$400,$A16))) -> 15288 | P16: =IF($A16="","",IF(O16=0,"",IF(_xlfn.MAXIFS('Histórico diário'!$F$5:$F$642,'Histórico diário'!$G$5:$G$642,$A16)>=_xlfn.MAXIFS(Diário!$F$5:$F$400,Diário!$H$5:$H$400,$A16),SUMPRODUCT(MAX(('Histórico diário'!$G$5:$G$642=$A16)*('Histórico diário'!$F$5:$F$642=O16)*'Histórico diário'!$A$5:$A$642)),SUMPRODUCT(MAX((Diário!$H$5:$H$400=$A16)*(Diário!$F$5:$F$400=O16)*Diário!$A$5:$A$400))))) -> 45745 | Q16: =IF(A16="","",IF(S16=0,"parcial",IF(L15=0,"n/d",L16/L15-1))) -> 0.59269003 | R16: =IF(A16="","","n/d") -> n/d | S16: =IF(A16="","",IF(B16=DAY(EOMONTH(A16,0)),1,0)) -> 1
A17: =IF(A16="","",IF(EDATE(A16,1)>MAX(MAX('Histórico diário'!$A$5:$A$642),MAX(Diário!$A$5:$A$400)),"",EDATE(A16,1))) -> 45748 | B17: =IF(A17="","",COUNTIFS('Histórico diário'!$G$5:$G$642,A17)+COUNTIFS(Diário!$H$5:$H$400,A17)) -> 30 | C17: =IF($A17="","",SUMIFS('Histórico diário'!$B$5:$B$642,'Histórico diário'!$G$5:$G$642,$A17)+SUMIFS(Diário!$B$5:$B$400,Diário!$H$5:$H$400,$A17)) -> 0 | D17: =IF($A17="","",SUMIFS('Histórico diário'!$E$5:$E$642,'Histórico diário'!$G$5:$G$642,$A17)+SUMIFS(Diário!$E$5:$E$400,Diário!$H$5:$H$400,$A17)) -> 0 | E17: =IF($A17="","",SUMIFS('Histórico diário'!$D$5:$D$642,'Histórico diário'!$G$5:$G$642,$A17)+SUMIFS(Diário!$D$5:$D$400,Diário!$H$5:$H$400,$A17)) -> 71158 | F17: =IF($A17="","",SUMIFS('Histórico diário'!$C$5:$C$642,'Histórico diário'!$G$5:$G$642,$A17)+SUMIFS(Diário!$C$5:$C$400,Diário!$H$5:$H$400,$A17)) -> 0 | G17: =IF(A17="","",SUM(C17:F17)) -> 71158 | H17: =IF($A17="","",C17*IFERROR(INDEX('Tarifas por mês'!$B$5:$B$25,MATCH($A17,'Tarifas por mês'!$A$5:$A$25,0)),Premissas!$C$4)) -> 0 | I17: =IF($A17="","",D17*IFERROR(INDEX('Tarifas por mês'!$C$5:$C$25,MATCH($A17,'Tarifas por mês'!$A$5:$A$25,0)),Premissas!$C$5)) -> 0 | J17: =IF($A17="","",E17*IFERROR(INDEX('Tarifas por mês'!$D$5:$D$25,MATCH($A17,'Tarifas por mês'!$A$5:$A$25,0)),Premissas!$C$6)) -> 42694.8 | K17: =IF($A17="","",F17*IFERROR(INDEX('Tarifas por mês'!$E$5:$E$25,MATCH($A17,'Tarifas por mês'!$A$5:$A$25,0)),Premissas!$C$7)) -> 0 | L17: =IF(A17="","",SUM(H17:K17)) -> 42694.8 | M17: =IF(A17="","",IF(G17=0,0,L17/G17)) -> 0.6 | N17: =IF(A17="","",IF(B17=0,0,G17/B17)) -> 2371.9333 | O17: =IF(A17="","",MAX(_xlfn.MAXIFS('Histórico diário'!$F$5:$F$642,'Histórico diário'!$G$5:$G$642,$A17),_xlfn.MAXIFS(Diário!$F$5:$F$400,Diário!$H$5:$H$400,$A17))) -> 13970 | P17: =IF($A17="","",IF(O17=0,"",IF(_xlfn.MAXIFS('Histórico diário'!$F$5:$F$642,'Histórico diário'!$G$5:$G$642,$A17)>=_xlfn.MAXIFS(Diário!$F$5:$F$400,Diário!$H$5:$H$400,$A17),SUMPRODUCT(MAX(('Histórico diário'!$G$5:$G$642=$A17)*('Histórico diário'!$F$5:$F$642=O17)*'Histórico diário'!$A$5:$A$642)),SUMPRODUCT(MAX((Diário!$H$5:$H$400=$A17)*(Diário!$F$5:$F$400=O17)*Diário!$A$5:$A$400))))) -> 45760 | Q17: =IF(A17="","",IF(S17=0,"parcial",IF(L16=0,"n/d",L17/L16-1))) -> 0.25036022 | R17: =IF(A17="","","n/d") -> n/d | S17: =IF(A17="","",IF(B17=DAY(EOMONTH(A17,0)),1,0)) -> 1
A18: =IF(A17="","",IF(EDATE(A17,1)>MAX(MAX('Histórico diário'!$A$5:$A$642),MAX(Diário!$A$5:$A$400)),"",EDATE(A17,1))) -> 45778 | B18: =IF(A18="","",COUNTIFS('Histórico diário'!$G$5:$G$642,A18)+COUNTIFS(Diário!$H$5:$H$400,A18)) -> 31 | C18: =IF($A18="","",SUMIFS('Histórico diário'!$B$5:$B$642,'Histórico diário'!$G$5:$G$642,$A18)+SUMIFS(Diário!$B$5:$B$400,Diário!$H$5:$H$400,$A18)) -> 0 | D18: =IF($A18="","",SUMIFS('Histórico diário'!$E$5:$E$642,'Histórico diário'!$G$5:$G$642,$A18)+SUMIFS(Diário!$E$5:$E$400,Diário!$H$5:$H$400,$A18)) -> 0 | E18: =IF($A18="","",SUMIFS('Histórico diário'!$D$5:$D$642,'Histórico diário'!$G$5:$G$642,$A18)+SUMIFS(Diário!$D$5:$D$400,Diário!$H$5:$H$400,$A18)) -> 116608 | F18: =IF($A18="","",SUMIFS('Histórico diário'!$C$5:$C$642,'Histórico diário'!$G$5:$G$642,$A18)+SUMIFS(Diário!$C$5:$C$400,Diário!$H$5:$H$400,$A18)) -> 0 | G18: =IF(A18="","",SUM(C18:F18)) -> 116608 | H18: =IF($A18="","",C18*IFERROR(INDEX('Tarifas por mês'!$B$5:$B$25,MATCH($A18,'Tarifas por mês'!$A$5:$A$25,0)),Premissas!$C$4)) -> 0 | I18: =IF($A18="","",D18*IFERROR(INDEX('Tarifas por mês'!$C$5:$C$25,MATCH($A18,'Tarifas por mês'!$A$5:$A$25,0)),Premissas!$C$5)) -> 0 | J18: =IF($A18="","",E18*IFERROR(INDEX('Tarifas por mês'!$D$5:$D$25,MATCH($A18,'Tarifas por mês'!$A$5:$A$25,0)),Premissas!$C$6)) -> 69964.8 | K18: =IF($A18="","",F18*IFERROR(INDEX('Tarifas por mês'!$E$5:$E$25,MATCH($A18,'Tarifas por mês'!$A$5:$A$25,0)),Premissas!$C$7)) -> 0 | L18: =IF(A18="","",SUM(H18:K18)) -> 69964.8 | M18: =IF(A18="","",IF(G18=0,0,L18/G18)) -> 0.6 | N18: =IF(A18="","",IF(B18=0,0,G18/B18)) -> 3761.5484 | O18: =IF(A18="","",MAX(_xlfn.MAXIFS('Histórico diário'!$F$5:$F$642,'Histórico diário'!$G$5:$G$642,$A18),_xlfn.MAXIFS(Diário!$F$5:$F$400,Diário!$H$5:$H$400,$A18))) -> 17672 | P18: =IF($A18="","",IF(O18=0,"",IF(_xlfn.MAXIFS('Histórico diário'!$F$5:$F$642,'Histórico diário'!$G$5:$G$642,$A18)>=_xlfn.MAXIFS(Diário!$F$5:$F$400,Diário!$H$5:$H$400,$A18),SUMPRODUCT(MAX(('Histórico diário'!$G$5:$G$642=$A18)*('Histórico diário'!$F$5:$F$642=O18)*'Histórico diário'!$A$5:$A$642)),SUMPRODUCT(MAX((Diário!$H$5:$H$400=$A18)*(Diário!$F$5:$F$400=O18)*Diário!$A$5:$A$400))))) -> 45781 | Q18: =IF(A18="","",IF(S18=0,"parcial",IF(L17=0,"n/d",L18/L17-1))) -> 0.63871947 | R18: =IF(A18="","","n/d") -> n/d | S18: =IF(A18="","",IF(B18=DAY(EOMONTH(A18,0)),1,0)) -> 1
A19: =IF(A18="","",IF(EDATE(A18,1)>MAX(MAX('Histórico diário'!$A$5:$A$642),MAX(Diário!$A$5:$A$400)),"",EDATE(A18,1))) -> 45809 | B19: =IF(A19="","",COUNTIFS('Histórico diário'!$G$5:$G$642,A19)+COUNTIFS(Diário!$H$5:$H$400,A19)) -> 30 | C19: =IF($A19="","",SUMIFS('Histórico diário'!$B$5:$B$642,'Histórico diário'!$G$5:$G$642,$A19)+SUMIFS(Diário!$B$5:$B$400,Diário!$H$5:$H$400,$A19)) -> 0 | D19: =IF($A19="","",SUMIFS('Histórico diário'!$E$5:$E$642,'Histórico diário'!$G$5:$G$642,$A19)+SUMIFS(Diário!$E$5:$E$400,Diário!$H$5:$H$400,$A19)) -> 0 | E19: =IF($A19="","",SUMIFS('Histórico diário'!$D$5:$D$642,'Histórico diário'!$G$5:$G$642,$A19)+SUMIFS(Diário!$D$5:$D$400,Diário!$H$5:$H$400,$A19)) -> 78258 | F19: =IF($A19="","",SUMIFS('Histórico diário'!$C$5:$C$642,'Histórico diário'!$G$5:$G$642,$A19)+SUMIFS(Diário!$C$5:$C$400,Diário!$H$5:$H$400,$A19)) -> 0 | G19: =IF(A19="","",SUM(C19:F19)) -> 78258 | H19: =IF($A19="","",C19*IFERROR(INDEX('Tarifas por mês'!$B$5:$B$25,MATCH($A19,'Tarifas por mês'!$A$5:$A$25,0)),Premissas!$C$4)) -> 0 | I19: =IF($A19="","",D19*IFERROR(INDEX('Tarifas por mês'!$C$5:$C$25,MATCH($A19,'Tarifas por mês'!$A$5:$A$25,0)),Premissas!$C$5)) -> 0 | J19: =IF($A19="","",E19*IFERROR(INDEX('Tarifas por mês'!$D$5:$D$25,MATCH($A19,'Tarifas por mês'!$A$5:$A$25,0)),Premissas!$C$6)) -> 46954.8 | K19: =IF($A19="","",F19*IFERROR(INDEX('Tarifas por mês'!$E$5:$E$25,MATCH($A19,'Tarifas por mês'!$A$5:$A$25,0)),Premissas!$C$7)) -> 0 | L19: =IF(A19="","",SUM(H19:K19)) -> 46954.8 | M19: =IF(A19="","",IF(G19=0,0,L19/G19)) -> 0.6 | N19: =IF(A19="","",IF(B19=0,0,G19/B19)) -> 2608.6 | O19: =IF(A19="","",MAX(_xlfn.MAXIFS('Histórico diário'!$F$5:$F$642,'Histórico diário'!$G$5:$G$642,$A19),_xlfn.MAXIFS(Diário!$F$5:$F$400,Diário!$H$5:$H$400,$A19))) -> 20036 | P19: =IF($A19="","",IF(O19=0,"",IF(_xlfn.MAXIFS('Histórico diário'!$F$5:$F$642,'Histórico diário'!$G$5:$G$642,$A19)>=_xlfn.MAXIFS(Diário!$F$5:$F$400,Diário!$H$5:$H$400,$A19),SUMPRODUCT(MAX(('Histórico diário'!$G$5:$G$642=$A19)*('Histórico diário'!$F$5:$F$642=O19)*'Histórico diário'!$A$5:$A$642)),SUMPRODUCT(MAX((Diário!$H$5:$H$400=$A19)*(Diário!$F$5:$F$400=O19)*Diário!$A$5:$A$400))))) -> 45819 | Q19: =IF(A19="","",IF(S19=0,"parcial",IF(L18=0,"n/d",L19/L18-1))) -> -0.32887967 | R19: =IF(A19="","","n/d") -> n/d | S19: =IF(A19="","",IF(B19=DAY(EOMONTH(A19,0)),1,0)) -> 1
A20: =IF(A19="","",IF(EDATE(A19,1)>MAX(MAX('Histórico diário'!$A$5:$A$642),MAX(Diário!$A$5:$A$400)),"",EDATE(A19,1))) -> 45839 | B20: =IF(A20="","",COUNTIFS('Histórico diário'!$G$5:$G$642,A20)+COUNTIFS(Diário!$H$5:$H$400,A20)) -> 31 | C20: =IF($A20="","",SUMIFS('Histórico diário'!$B$5:$B$642,'Histórico diário'!$G$5:$G$642,$A20)+SUMIFS(Diário!$B$5:$B$400,Diário!$H$5:$H$400,$A20)) -> 0 | D20: =IF($A20="","",SUMIFS('Histórico diário'!$E$5:$E$642,'Histórico diário'!$G$5:$G$642,$A20)+SUMIFS(Diário!$E$5:$E$400,Diário!$H$5:$H$400,$A20)) -> 0 | E20: =IF($A20="","",SUMIFS('Histórico diário'!$D$5:$D$642,'Histórico diário'!$G$5:$G$642,$A20)+SUMIFS(Diário!$D$5:$D$400,Diário!$H$5:$H$400,$A20)) -> 38669 | F20: =IF($A20="","",SUMIFS('Histórico diário'!$C$5:$C$642,'Histórico diário'!$G$5:$G$642,$A20)+SUMIFS(Diário!$C$5:$C$400,Diário!$H$5:$H$400,$A20)) -> 0 | G20: =IF(A20="","",SUM(C20:F20)) -> 38669 | H20: =IF($A20="","",C20*IFERROR(INDEX('Tarifas por mês'!$B$5:$B$25,MATCH($A20,'Tarifas por mês'!$A$5:$A$25,0)),Premissas!$C$4)) -> 0 | I20: =IF($A20="","",D20*IFERROR(INDEX('Tarifas por mês'!$C$5:$C$25,MATCH($A20,'Tarifas por mês'!$A$5:$A$25,0)),Premissas!$C$5)) -> 0 | J20: =IF($A20="","",E20*IFERROR(INDEX('Tarifas por mês'!$D$5:$D$25,MATCH($A20,'Tarifas por mês'!$A$5:$A$25,0)),Premissas!$C$6)) -> 23201.4 | K20: =IF($A20="","",F20*IFERROR(INDEX('Tarifas por mês'!$E$5:$E$25,MATCH($A20,'Tarifas por mês'!$A$5:$A$25,0)),Premissas!$C$7)) -> 0 | L20: =IF(A20="","",SUM(H20:K20)) -> 23201.4 | M20: =IF(A20="","",IF(G20=0,0,L20/G20)) -> 0.6 | N20: =IF(A20="","",IF(B20=0,0,G20/B20)) -> 1247.3871 | O20: =IF(A20="","",MAX(_xlfn.MAXIFS('Histórico diário'!$F$5:$F$642,'Histórico diário'!$G$5:$G$642,$A20),_xlfn.MAXIFS(Diário!$F$5:$F$400,Diário!$H$5:$H$400,$A20))) -> 8227 | P20: =IF($A20="","",IF(O20=0,"",IF(_xlfn.MAXIFS('Histórico diário'!$F$5:$F$642,'Histórico diário'!$G$5:$G$642,$A20)>=_xlfn.MAXIFS(Diário!$F$5:$F$400,Diário!$H$5:$H$400,$A20),SUMPRODUCT(MAX(('Histórico diário'!$G$5:$G$642=$A20)*('Histórico diário'!$F$5:$F$642=O20)*'Histórico diário'!$A$5:$A$642)),SUMPRODUCT(MAX((Diário!$H$5:$H$400=$A20)*(Diário!$F$5:$F$400=O20)*Diário!$A$5:$A$400))))) -> 45849 | Q20: =IF(A20="","",IF(S20=0,"parcial",IF(L19=0,"n/d",L20/L19-1))) -> -0.50587799 | R20: =IF(A20="","","n/d") -> n/d | S20: =IF(A20="","",IF(B20=DAY(EOMONTH(A20,0)),1,0)) -> 1
A21: =IF(A20="","",IF(EDATE(A20,1)>MAX(MAX('Histórico diário'!$A$5:$A$642),MAX(Diário!$A$5:$A$400)),"",EDATE(A20,1))) -> 45870 | B21: =IF(A21="","",COUNTIFS('Histórico diário'!$G$5:$G$642,A21)+COUNTIFS(Diário!$H$5:$H$400,A21)) -> 31 | C21: =IF($A21="","",SUMIFS('Histórico diário'!$B$5:$B$642,'Histórico diário'!$G$5:$G$642,$A21)+SUMIFS(Diário!$B$5:$B$400,Diário!$H$5:$H$400,$A21)) -> 0 | D21: =IF($A21="","",SUMIFS('Histórico diário'!$E$5:$E$642,'Histórico diário'!$G$5:$G$642,$A21)+SUMIFS(Diário!$E$5:$E$400,Diário!$H$5:$H$400,$A21)) -> 0 | E21: =IF($A21="","",SUMIFS('Histórico diário'!$D$5:$D$642,'Histórico diário'!$G$5:$G$642,$A21)+SUMIFS(Diário!$D$5:$D$400,Diário!$H$5:$H$400,$A21)) -> 29419 | F21: =IF($A21="","",SUMIFS('Histórico diário'!$C$5:$C$642,'Histórico diário'!$G$5:$G$642,$A21)+SUMIFS(Diário!$C$5:$C$400,Diário!$H$5:$H$400,$A21)) -> 0 | G21: =IF(A21="","",SUM(C21:F21)) -> 29419 | H21: =IF($A21="","",C21*IFERROR(INDEX('Tarifas por mês'!$B$5:$B$25,MATCH($A21,'Tarifas por mês'!$A$5:$A$25,0)),Premissas!$C$4)) -> 0 | I21: =IF($A21="","",D21*IFERROR(INDEX('Tarifas por mês'!$C$5:$C$25,MATCH($A21,'Tarifas por mês'!$A$5:$A$25,0)),Premissas!$C$5)) -> 0 | J21: =IF($A21="","",E21*IFERROR(INDEX('Tarifas por mês'!$D$5:$D$25,MATCH($A21,'Tarifas por mês'!$A$5:$A$25,0)),Premissas!$C$6)) -> 17651.4 | K21: =IF($A21="","",F21*IFERROR(INDEX('Tarifas por mês'!$E$5:$E$25,MATCH($A21,'Tarifas por mês'!$A$5:$A$25,0)),Premissas!$C$7)) -> 0 | L21: =IF(A21="","",SUM(H21:K21)) -> 17651.4 | M21: =IF(A21="","",IF(G21=0,0,L21/G21)) -> 0.6 | N21: =IF(A21="","",IF(B21=0,0,G21/B21)) -> 949 | O21: =IF(A21="","",MAX(_xlfn.MAXIFS('Histórico diário'!$F$5:$F$642,'Histórico diário'!$G$5:$G$642,$A21),_xlfn.MAXIFS(Diário!$F$5:$F$400,Diário!$H$5:$H$400,$A21))) -> 6765 | P21: =IF($A21="","",IF(O21=0,"",IF(_xlfn.MAXIFS('Histórico diário'!$F$5:$F$642,'Histórico diário'!$G$5:$G$642,$A21)>=_xlfn.MAXIFS(Diário!$F$5:$F$400,Diário!$H$5:$H$400,$A21),SUMPRODUCT(MAX(('Histórico diário'!$G$5:$G$642=$A21)*('Histórico diário'!$F$5:$F$642=O21)*'Histórico diário'!$A$5:$A$642)),SUMPRODUCT(MAX((Diário!$H$5:$H$400=$A21)*(Diário!$F$5:$F$400=O21)*Diário!$A$5:$A$400))))) -> 45881 | Q21: =IF(A21="","",IF(S21=0,"parcial",IF(L20=0,"n/d",L21/L20-1))) -> -0.2392097 | R21: =IF(A21="","","n/d") -> n/d | S21: =IF(A21="","",IF(B21=DAY(EOMONTH(A21,0)),1,0)) -> 1
A22: =IF(A21="","",IF(EDATE(A21,1)>MAX(MAX('Histórico diário'!$A$5:$A$642),MAX(Diário!$A$5:$A$400)),"",EDATE(A21,1))) -> 45901 | B22: =IF(A22="","",COUNTIFS('Histórico diário'!$G$5:$G$642,A22)+COUNTIFS(Diário!$H$5:$H$400,A22)) -> 30 | C22: =IF($A22="","",SUMIFS('Histórico diário'!$B$5:$B$642,'Histórico diário'!$G$5:$G$642,$A22)+SUMIFS(Diário!$B$5:$B$400,Diário!$H$5:$H$400,$A22)) -> 0 | D22: =IF($A22="","",SUMIFS('Histórico diário'!$E$5:$E$642,'Histórico diário'!$G$5:$G$642,$A22)+SUMIFS(Diário!$E$5:$E$400,Diário!$H$5:$H$400,$A22)) -> 15378 | E22: =IF($A22="","",SUMIFS('Histórico diário'!$D$5:$D$642,'Histórico diário'!$G$5:$G$642,$A22)+SUMIFS(Diário!$D$5:$D$400,Diário!$H$5:$H$400,$A22)) -> 44500 | F22: =IF($A22="","",SUMIFS('Histórico diário'!$C$5:$C$642,'Histórico diário'!$G$5:$G$642,$A22)+SUMIFS(Diário!$C$5:$C$400,Diário!$H$5:$H$400,$A22)) -> 0 | G22: =IF(A22="","",SUM(C22:F22)) -> 59878 | H22: =IF($A22="","",C22*IFERROR(INDEX('Tarifas por mês'!$B$5:$B$25,MATCH($A22,'Tarifas por mês'!$A$5:$A$25,0)),Premissas!$C$4)) -> 0 | I22: =IF($A22="","",D22*IFERROR(INDEX('Tarifas por mês'!$C$5:$C$25,MATCH($A22,'Tarifas por mês'!$A$5:$A$25,0)),Premissas!$C$5)) -> 8304.12 | J22: =IF($A22="","",E22*IFERROR(INDEX('Tarifas por mês'!$D$5:$D$25,MATCH($A22,'Tarifas por mês'!$A$5:$A$25,0)),Premissas!$C$6)) -> 26700 | K22: =IF($A22="","",F22*IFERROR(INDEX('Tarifas por mês'!$E$5:$E$25,MATCH($A22,'Tarifas por mês'!$A$5:$A$25,0)),Premissas!$C$7)) -> 0 | L22: =IF(A22="","",SUM(H22:K22)) -> 35004.12 | M22: =IF(A22="","",IF(G22=0,0,L22/G22)) -> 0.58459067 | N22: =IF(A22="","",IF(B22=0,0,G22/B22)) -> 1995.9333 | O22: =IF(A22="","",MAX(_xlfn.MAXIFS('Histórico diário'!$F$5:$F$642,'Histórico diário'!$G$5:$G$642,$A22),_xlfn.MAXIFS(Diário!$F$5:$F$400,Diário!$H$5:$H$400,$A22))) -> 16385 | P22: =IF($A22="","",IF(O22=0,"",IF(_xlfn.MAXIFS('Histórico diário'!$F$5:$F$642,'Histórico diário'!$G$5:$G$642,$A22)>=_xlfn.MAXIFS(Diário!$F$5:$F$400,Diário!$H$5:$H$400,$A22),SUMPRODUCT(MAX(('Histórico diário'!$G$5:$G$642=$A22)*('Histórico diário'!$F$5:$F$642=O22)*'Histórico diário'!$A$5:$A$642)),SUMPRODUCT(MAX((Diário!$H$5:$H$400=$A22)*(Diário!$F$5:$F$400=O22)*Diário!$A$5:$A$400))))) -> 45919 | Q22: =IF(A22="","",IF(S22=0,"parcial",IF(L21=0,"n/d",L22/L21-1))) -> 0.98307896 | R22: =IF(A22="","","n/d") -> n/d | S22: =IF(A22="","",IF(B22=DAY(EOMONTH(A22,0)),1,0)) -> 1
A23: =IF(A22="","",IF(EDATE(A22,1)>MAX(MAX('Histórico diário'!$A$5:$A$642),MAX(Diário!$A$5:$A$400)),"",EDATE(A22,1))) -> 45931 | B23: =IF(A23="","",COUNTIFS('Histórico diário'!$G$5:$G$642,A23)+COUNTIFS(Diário!$H$5:$H$400,A23)) -> 31 | C23: =IF($A23="","",SUMIFS('Histórico diário'!$B$5:$B$642,'Histórico diário'!$G$5:$G$642,$A23)+SUMIFS(Diário!$B$5:$B$400,Diário!$H$5:$H$400,$A23)) -> 0 | D23: =IF($A23="","",SUMIFS('Histórico diário'!$E$5:$E$642,'Histórico diário'!$G$5:$G$642,$A23)+SUMIFS(Diário!$E$5:$E$400,Diário!$H$5:$H$400,$A23)) -> 46321 | E23: =IF($A23="","",SUMIFS('Histórico diário'!$D$5:$D$642,'Histórico diário'!$G$5:$G$642,$A23)+SUMIFS(Diário!$D$5:$D$400,Diário!$H$5:$H$400,$A23)) -> 12 | F23: =IF($A23="","",SUMIFS('Histórico diário'!$C$5:$C$642,'Histórico diário'!$G$5:$G$642,$A23)+SUMIFS(Diário!$C$5:$C$400,Diário!$H$5:$H$400,$A23)) -> 0 | G23: =IF(A23="","",SUM(C23:F23)) -> 46333 | H23: =IF($A23="","",C23*IFERROR(INDEX('Tarifas por mês'!$B$5:$B$25,MATCH($A23,'Tarifas por mês'!$A$5:$A$25,0)),Premissas!$C$4)) -> 0 | I23: =IF($A23="","",D23*IFERROR(INDEX('Tarifas por mês'!$C$5:$C$25,MATCH($A23,'Tarifas por mês'!$A$5:$A$25,0)),Premissas!$C$5)) -> 25013.34 | J23: =IF($A23="","",E23*IFERROR(INDEX('Tarifas por mês'!$D$5:$D$25,MATCH($A23,'Tarifas por mês'!$A$5:$A$25,0)),Premissas!$C$6)) -> 7.2 | K23: =IF($A23="","",F23*IFERROR(INDEX('Tarifas por mês'!$E$5:$E$25,MATCH($A23,'Tarifas por mês'!$A$5:$A$25,0)),Premissas!$C$7)) -> 0 | L23: =IF(A23="","",SUM(H23:K23)) -> 25020.54 | M23: =IF(A23="","",IF(G23=0,0,L23/G23)) -> 0.54001554 | N23: =IF(A23="","",IF(B23=0,0,G23/B23)) -> 1494.6129 | O23: =IF(A23="","",MAX(_xlfn.MAXIFS('Histórico diário'!$F$5:$F$642,'Histórico diário'!$G$5:$G$642,$A23),_xlfn.MAXIFS(Diário!$F$5:$F$400,Diário!$H$5:$H$400,$A23))) -> 13571 | P23: =IF($A23="","",IF(O23=0,"",IF(_xlfn.MAXIFS('Histórico diário'!$F$5:$F$642,'Histórico diário'!$G$5:$G$642,$A23)>=_xlfn.MAXIFS(Diário!$F$5:$F$400,Diário!$H$5:$H$400,$A23),SUMPRODUCT(MAX(('Histórico diário'!$G$5:$G$642=$A23)*('Histórico diário'!$F$5:$F$642=O23)*'Histórico diário'!$A$5:$A$642)),SUMPRODUCT(MAX((Diário!$H$5:$H$400=$A23)*(Diário!$F$5:$F$400=O23)*Diário!$A$5:$A$400))))) -> 45951 | Q23: =IF(A23="","",IF(S23=0,"parcial",IF(L22=0,"n/d",L23/L22-1))) -> -0.28521157 | R23: =IF(A23="","","n/d") -> n/d | S23: =IF(A23="","",IF(B23=DAY(EOMONTH(A23,0)),1,0)) -> 1
